<?xml version="1.0" encoding="utf-8"?>

<robot name="moveo_description">
  <link
    name="base_link">
    <inertial>
      <origin
        xyz="1.4509E-05 1.4418E-08 0.037157"
        rpy="0 0 0" />
      <mass
        value="0.63758" />
      <inertia
        ixx="0.0015156"
        ixy="-4.4377E-10"
        ixz="-1.5691E-07"
        iyy="0.0015149"
        iyz="-1.9031E-11"
        izz="0.0026238" />
    </inertial>
    <visual>
      <origin
        xyz="0 0 0"
        rpy="0 0 0" />
      <geometry>
        <mesh
          filename="package://moveo_description/new_meshes/base_link.STL" />
      </geometry>
      <material
        name="">
        <color
          rgba="0.79216 0.81961 0.93333 1" />
      </material>
    </visual>
    <collision>
      <origin
        xyz="0 0 0"
        rpy="0 0 0" />
      <geometry>
        <mesh
          filename="package://moveo_description/new_meshes/base_link.STL" />
      </geometry>
    </collision>
  </link>
  <link
    name="link_1">
    <inertial>
      <origin
        xyz="-9.1738E-05 -1.2493E-05 0.083097"
        rpy="0 0 0" />
      <mass
        value="1.5994" />
      <inertia
        ixx="0.0068504"
        ixy="1.2404E-07"
        ixz="3.9315E-07"
        iyy="0.0083964"
        iyz="-3.7032E-07"
        izz="0.0063085" />
    </inertial>
    <visual>
      <origin
        xyz="0 0 0"
        rpy="0 0 0" />
      <geometry>
        <mesh
          filename="package://moveo_description/new_meshes/link_1.STL" />
      </geometry>
      <material
        name="">
        <color
          rgba="0.027451 0.27059 1 1" />
      </material>
    </visual>
    <collision>
      <origin
        xyz="0 0 0"
        rpy="0 0 0" />
      <geometry>
        <mesh
          filename="package://moveo_description/new_meshes/link_1.STL" />
      </geometry>
    </collision>
  </link>
  <joint
    name="joint_1"
    type="revolute">
    <origin
      xyz="0 0 0.066"
      rpy="0 0 0" />
    <parent
      link="base_link" />
    <child
      link="link_1" />
    <axis
      xyz="0 0 1" />
    <limit
      lower="-1.57"
      upper="1.57"
      effort="10"
      velocity="10" />
  </joint>
  <link
    name="link_2">
    <inertial>
      <origin
        xyz="-0.00044845 -2.0917E-05 0.075983"
        rpy="0 0 0" />
      <mass
        value="1.7861" />
      <inertia
        ixx="0.0048246"
        ixy="-1.0807E-06"
        ixz="-9.752E-06"
        iyy="0.0049236"
        iyz="1.8268E-07"
        izz="0.002844" />
    </inertial>
    <visual>
      <origin
        xyz="0 0 0"
        rpy="0 0 0" />
      <geometry>
        <mesh
          filename="package://moveo_description/new_meshes/link_2.STL" />
      </geometry>
      <material
        name="">
        <color
          rgba="0.75294 0.75294 0.75294 1" />
      </material>
    </visual>
    <collision>
      <origin
        xyz="0 0 0"
        rpy="0 0 0" />
      <geometry>
        <mesh
          filename="package://moveo_description/new_meshes/link_2.STL" />
      </geometry>
    </collision>
  </link>
  <joint
    name="joint_2"
    type="revolute">
    <origin
      xyz="0 0 0.1655"
      rpy="0 0 0" />
    <parent
      link="link_1" />
    <child
      link="link_2" />
    <axis
      xyz="1 0 0" />
    <limit
      lower="-1.57"
      upper="1.57"
      effort="10"
      velocity="10" />
  </joint>
  <link
    name="link_3">
    <inertial>
      <origin
        xyz="-0.00035774 -8.5304E-05 0.037984"
        rpy="0 0 0" />
      <mass
        value="0.65465" />
      <inertia
        ixx="0.0019581"
        ixy="-5.4089E-09"
        ixz="2.1501E-06"
        iyy="0.0016825"
        iyz="-5.977E-07"
        izz="0.00042425" />
    </inertial>
    <visual>
      <origin
        xyz="0 0 0"
        rpy="0 0 0" />
      <geometry>
        <mesh
          filename="package://moveo_description/new_meshes/link_3.STL" />
      </geometry>
      <material
        name="">
        <color
          rgba="1 1 1 1" />
      </material>
    </visual>
    <collision>
      <origin
        xyz="0 0 0"
        rpy="0 0 0" />
      <geometry>
        <mesh
          filename="package://moveo_description/new_meshes/link_3.STL" />
      </geometry>
    </collision>
  </link>
  <joint
    name="joint_3"
    type="revolute">
    <origin
      xyz="0.001 0 0.22112"
      rpy="0 0 0" />
    <parent
      link="link_2" />
    <child
      link="link_3" />
    <axis
      xyz="-1 0 0" />
    <limit
      lower="-1.57"
      upper="1.57"
      effort="10"
      velocity="10" />
  </joint>
  <link
    name="link_4">
    <inertial>
      <origin
        xyz="-4.4474E-05 0.00088881 0.051737"
        rpy="0 0 0" />
      <mass
        value="0.26135" />
      <inertia
        ixx="0.00050576"
        ixy="1.9078E-07"
        ixz="6.4065E-07"
        iyy="0.00059141"
        iyz="9.8116E-06"
        izz="0.00028852" />
    </inertial>
    <visual>
      <origin
        xyz="0 0 0"
        rpy="0 0 0" />
      <geometry>
        <mesh
          filename="package://moveo_description/new_meshes/link_4.STL" />
      </geometry>
      <material
        name="">
        <color
          rgba="0.29412 0.29412 0.29412 1" />
      </material>
    </visual>
    <collision>
      <origin
        xyz="0 0 0"
        rpy="0 0 0" />
      <geometry>
        <mesh
          filename="package://moveo_description/new_meshes/link_4.STL" />
      </geometry>
    </collision>
  </link>
  <joint
    name="joint_4"
    type="revolute">
    <origin
      xyz="0 0 0.128"
      rpy="0 0 0" />
    <parent
      link="link_3" />
    <child
      link="link_4" />
    <axis
      xyz="0 0 1" />
    <limit
      lower="-1.57"
      upper="1.57"
      effort="10"
      velocity="10" />
  </joint>
  <link
    name="link_5">
    <inertial>
      <origin
        xyz="-0.00038809 8.4249E-05 0.013155"
        rpy="0 0 0" />
      <mass
        value="0.18973" />
      <inertia
        ixx="0.00011324"
        ixy="-9.0102E-08"
        ixz="2.5517E-07"
        iyy="8.2477E-05"
        iyz="-7.6831E-08"
        izz="6.2461E-05" />
    </inertial>
    <visual>
      <origin
        xyz="0 0 0"
        rpy="0 0 0" />
      <geometry>
        <mesh
          filename="package://moveo_description/new_meshes/link_5.STL" />
      </geometry>
      <material
        name="">
        <color
          rgba="0.098039 0.098039 0.098039 1" />
      </material>
    </visual>
    <collision>
      <origin
        xyz="0 0 0"
        rpy="0 0 0" />
      <geometry>
        <mesh
          filename="package://moveo_description/new_meshes/link_5.STL" />
      </geometry>
    </collision>
  </link>
  <joint
    name="joint_5"
    type="revolute">
    <origin
      xyz="0 0 0.095"
      rpy="0 0 0" />
    <parent
      link="link_4" />
    <child
      link="link_5" />
    <axis
      xyz="-1 0 0" />
    <limit
      lower="-1.57"
      upper="1.57"
      effort="10"
      velocity="10" />
  </joint>
</robot>