<?xml version="1.0" encoding="utf-8"?>

<robot
  name="moveo_description">
  <link
    name="base_link">
    <inertial>
      <origin
        xyz="0.036546 -0.050619 0.19984"
        rpy="0 0 0" />
      <mass
        value="7.7854" />
      <inertia
        ixx="0.12581"
        ixy="-2.1715E-05"
        ixz="-0.00071014"
        iyy="0.25036"
        iyz="-2.99E-05"
        izz="0.12731" />
    </inertial>
    <visual>
      <origin
        xyz="0 0 0"
        rpy="0 0 0" />
      <geometry>
        <mesh
          filename="package://moveo_description/new_meshes/base_link.STL" />
      </geometry>
      <material
        name="">
        <color
          rgba="0.79216 0.81961 0.93333 1" />
      </material>
    </visual>
    <collision>
      <origin
        xyz="0 0 0"
        rpy="0 0 0" />
      <geometry>
        <mesh
          filename="package://moveo_description/new_meshes/base_link.STL" />
      </geometry>
    </collision>
  </link>
  <link
    name="link1">
    <inertial>
      <origin
        xyz="-3.5798E-05 -4.8751E-06 0.071269"
        rpy="0 0 0" />
      <mass
        value="4.0987" />
      <inertia
        ixx="0.0079906"
        ixy="1.2404E-07"
        ixz="3.9315E-07"
        iyy="0.0090842"
        iyz="-3.7032E-07"
        izz="0.0069945" />
    </inertial>
    <visual>
      <origin
        xyz="0 0 0"
        rpy="0 0 0" />
      <geometry>
        <mesh
          filename="package://moveo_description/new_meshes/link1.STL" />
      </geometry>
      <material
        name="">
        <color
          rgba="0.027451 0.27059 1 1" />
      </material>
    </visual>
    <collision>
      <origin
        xyz="0 0 0"
        rpy="0 0 0" />
      <geometry>
        <mesh
          filename="package://moveo_description/new_meshes/link1.STL" />
      </geometry>
    </collision>
  </link>
  <joint
    name="joint1"
    type="revolute">
    <origin
      xyz="0 -0.2425 0.017144"
      rpy="0 0 -0.3927" />
    <parent
      link="base_link" />
    <child
      link="link1" />
    <axis
      xyz="0 0 1" />
    <limit
      lower="-1.57"
      upper="1.57"
      effort="10"
      velocity="10" />
  </joint>
  <link
    name="link2">
    <inertial>
      <origin
        xyz="-0.00182 -1.9891E-05 0.077801"
        rpy="0 0 0" />
      <mass
        value="1.8918" />
      <inertia
        ixx="0.0048497"
        ixy="-1.0695E-06"
        ixz="-9.7137E-06"
        iyy="0.0049726"
        iyz="1.8337E-07"
        izz="0.002893" />
    </inertial>
    <visual>
      <origin
        xyz="0 0 0"
        rpy="0 0 0" />
      <geometry>
        <mesh
          filename="package://moveo_description/new_meshes/link2.STL" />
      </geometry>
      <material
        name="">
        <color
          rgba="0.75294 0.75294 0.75294 1" />
      </material>
    </visual>
    <collision>
      <origin
        xyz="0 0 0"
        rpy="0 0 0" />
      <geometry>
        <mesh
          filename="package://moveo_description/new_meshes/link2.STL" />
      </geometry>
    </collision>
  </link>
  <joint
    name="joint2"
    type="revolute">
    <origin
      xyz="0 0 0.1655"
      rpy="0 0 0" />
    <parent
      link="link1" />
    <child
      link="link2" />
    <axis
      xyz="1 0 0" />
    <limit
      lower="-1.57"
      upper="1.57"
      effort="10"
      velocity="10" />
  </joint>
</robot>